[INFO    ] [Client  ] Initializing client
[INFO    ] [Client  ] Logged on as freefbot#3056
Ignoring exception in command None:
discord.ext.commands.errors.CommandNotFound: Command "lel" is not found
Ignoring exception in command supl:
Traceback (most recent call last):
  File "C:\Program Files (x86)\Python37-32\lib\site-packages\discord\ext\commands\core.py", line 62, in wrapped
    ret = await coro(*args, **kwargs)
  File "C:\Users\jakub\Desktop\freefbot\src\commands.py", line 110, in supl
    await ctx.send(suplovani(target, Config.username, Config.password))
  File "C:\Users\jakub\Desktop\freefbot\src\command_modules\suplovani.py", line 177, in suplovani
    return pdf_to_string(f'{DOWNLOAD_PATH}/{fname}', target)
  File "C:\Users\jakub\Desktop\freefbot\src\command_modules\suplovani.py", line 35, in pdf_to_string
    data = [[col['text'] for col in itemgetter(*COLS)(row)] for row in data]
  File "C:\Users\jakub\Desktop\freefbot\src\command_modules\suplovani.py", line 35, in <listcomp>
    data = [[col['text'] for col in itemgetter(*COLS)(row)] for row in data]
IndexError: list index out of range

The above exception was the direct cause of the following exception:

Traceback (most recent call last):
  File "C:\Program Files (x86)\Python37-32\lib\site-packages\discord\ext\commands\bot.py", line 898, in invoke
    await ctx.command.invoke(ctx)
  File "C:\Program Files (x86)\Python37-32\lib\site-packages\discord\ext\commands\core.py", line 615, in invoke
    await injected(*ctx.args, **ctx.kwargs)
  File "C:\Program Files (x86)\Python37-32\lib\site-packages\discord\ext\commands\core.py", line 71, in wrapped
    raise CommandInvokeError(exc) from exc
discord.ext.commands.errors.CommandInvokeError: Command raised an exception: IndexError: list index out of range
[INFO    ] [Client  ] Logged on as freefbot#3056
Ignoring exception in command supl:
Traceback (most recent call last):
  File "C:\Program Files (x86)\Python37-32\lib\site-packages\discord\ext\commands\core.py", line 62, in wrapped
    ret = await coro(*args, **kwargs)
  File "C:\Users\jakub\Desktop\freefbot\src\commands.py", line 110, in supl
    await ctx.send(suplovani(target, Config.username, Config.password))
  File "C:\Users\jakub\Desktop\freefbot\src\command_modules\suplovani.py", line 177, in suplovani
    return pdf_to_string(f'{DOWNLOAD_PATH}/{fname}', target)
  File "C:\Users\jakub\Desktop\freefbot\src\command_modules\suplovani.py", line 35, in pdf_to_string
    data = [[col['text'] for col in itemgetter(*COLS)(row)] for row in data]
  File "C:\Users\jakub\Desktop\freefbot\src\command_modules\suplovani.py", line 35, in <listcomp>
    data = [[col['text'] for col in itemgetter(*COLS)(row)] for row in data]
IndexError: list index out of range

The above exception was the direct cause of the following exception:

Traceback (most recent call last):
  File "C:\Program Files (x86)\Python37-32\lib\site-packages\discord\ext\commands\bot.py", line 898, in invoke
    await ctx.command.invoke(ctx)
  File "C:\Program Files (x86)\Python37-32\lib\site-packages\discord\ext\commands\core.py", line 615, in invoke
    await injected(*ctx.args, **ctx.kwargs)
  File "C:\Program Files (x86)\Python37-32\lib\site-packages\discord\ext\commands\core.py", line 71, in wrapped
    raise CommandInvokeError(exc) from exc
discord.ext.commands.errors.CommandInvokeError: Command raised an exception: IndexError: list index out of range
Ignoring exception in command log:
Traceback (most recent call last):
  File "C:\Program Files (x86)\Python37-32\lib\site-packages\discord\ext\commands\core.py", line 62, in wrapped
    ret = await coro(*args, **kwargs)
  File "C:\Users\jakub\Desktop\freefbot\src\commands.py", line 120, in log
    await ctx.send(f'```python\n{Logger.get_log()}```')
  File "C:\Program Files (x86)\Python37-32\lib\site-packages\discord\abc.py", line 772, in send
    data = await state.http.send_message(channel.id, content, tts=tts, embed=embed, nonce=nonce)
  File "C:\Program Files (x86)\Python37-32\lib\site-packages\discord\http.py", line 214, in request
    raise HTTPException(r, data)
discord.errors.HTTPException: BAD REQUEST (status code: 400): Invalid Form Body
In content: Must be 2000 or fewer in length.

The above exception was the direct cause of the following exception:

Traceback (most recent call last):
  File "C:\Program Files (x86)\Python37-32\lib\site-packages\discord\ext\commands\bot.py", line 898, in invoke
    await ctx.command.invoke(ctx)
  File "C:\Program Files (x86)\Python37-32\lib\site-packages\discord\ext\commands\core.py", line 615, in invoke
    await injected(*ctx.args, **ctx.kwargs)
  File "C:\Program Files (x86)\Python37-32\lib\site-packages\discord\ext\commands\core.py", line 71, in wrapped
    raise CommandInvokeError(exc) from exc
discord.ext.commands.errors.CommandInvokeError: Command raised an exception: HTTPException: BAD REQUEST (status code: 400): Invalid Form Body
In content: Must be 2000 or fewer in length.
Ignoring exception in command log:
Traceback (most recent call last):
  File "C:\Program Files (x86)\Python37-32\lib\site-packages\discord\ext\commands\core.py", line 62, in wrapped
    ret = await coro(*args, **kwargs)
  File "C:\Users\jakub\Desktop\freefbot\src\commands.py", line 120, in log
    await ctx.send(f'```python\n{Logger.get_log()}```')
  File "C:\Program Files (x86)\Python37-32\lib\site-packages\discord\abc.py", line 772, in send
    data = await state.http.send_message(channel.id, content, tts=tts, embed=embed, nonce=nonce)
  File "C:\Program Files (x86)\Python37-32\lib\site-packages\discord\http.py", line 214, in request
    raise HTTPException(r, data)
discord.errors.HTTPException: BAD REQUEST (status code: 400): Invalid Form Body
In content: Must be 2000 or fewer in length.

The above exception was the direct cause of the following exception:

Traceback (most recent call last):
  File "C:\Program Files (x86)\Python37-32\lib\site-packages\discord\ext\commands\bot.py", line 898, in invoke
    await ctx.command.invoke(ctx)
  File "C:\Program Files (x86)\Python37-32\lib\site-packages\discord\ext\commands\core.py", line 615, in invoke
    await injected(*ctx.args, **ctx.kwargs)
  File "C:\Program Files (x86)\Python37-32\lib\site-packages\discord\ext\commands\core.py", line 71, in wrapped
    raise CommandInvokeError(exc) from exc
discord.ext.commands.errors.CommandInvokeError: Command raised an exception: HTTPException: BAD REQUEST (status code: 400): Invalid Form Body
In content: Must be 2000 or fewer in length.
